2019-11-01 06:07:26,489 p=5229 u=bala |    hosts (2):
2019-11-01 06:07:26,489 p=5229 u=bala |      35.226.36.29
2019-11-01 06:07:26,489 p=5229 u=bala |      34.69.108.215
2019-11-01 06:34:59,379 p=5720 u=bala |  ERROR! Syntax Error while loading YAML.
  mapping values are not allowed in this context

The error appears to be in '/home/bala/testansible.yml': line 2, column 9, but may
be elsewhere in the file depending on the exact syntax problem.

The offending line appears to be:

hosts: /home/bala/hosts
 become : yes
        ^ here

2019-11-01 06:37:56,510 p=5756 u=bala |  ERROR! Syntax Error while loading YAML.
  mapping values are not allowed in this context

The error appears to be in '/home/bala/testansible.yml': line 2, column 9, but may
be elsewhere in the file depending on the exact syntax problem.

The offending line appears to be:

hosts: test
 become : yes
        ^ here

2019-11-01 06:46:02,204 p=5851 u=bala |  ERROR! Syntax Error while loading YAML.
  mapping values are not allowed in this context

The error appears to be in '/home/bala/testansible.yml': line 2, column 10, but may
be elsewhere in the file depending on the exact syntax problem.

The offending line appears to be:

 ---
  - hosts: test
         ^ here

2019-11-01 06:46:58,597 p=5872 u=bala |  ERROR! Syntax Error while loading YAML.
  mapping values are not allowed in this context

The error appears to be in '/home/bala/testansible.yml': line 2, column 10, but may
be elsewhere in the file depending on the exact syntax problem.

The offending line appears to be:

 ---
  - hosts: test
         ^ here

2019-11-01 06:49:13,275 p=5895 u=bala |  ERROR! Syntax Error while loading YAML.
  mapping values are not allowed in this context

The error appears to be in '/home/bala/testansible.yml': line 2, column 10, but may
be elsewhere in the file depending on the exact syntax problem.

The offending line appears to be:

 ---
  - hosts: test
         ^ here

2019-11-01 06:50:49,597 p=5916 u=bala |  PLAY [test] ********************************************************************
2019-11-01 06:50:49,606 p=5916 u=bala |  TASK [Gathering Facts] *********************************************************
2019-11-01 06:50:49,751 p=5916 u=bala |  fatal: [35.226.36.29]: UNREACHABLE! => {"changed": false, "msg": "Failed to connect to the host via ssh: Permission denied (publickey,gssapi-keyex,gssapi-with-mic).", "unreachable": true}
2019-11-01 06:50:49,754 p=5916 u=bala |  fatal: [34.69.108.215]: UNREACHABLE! => {"changed": false, "msg": "Failed to connect to the host via ssh: Permission denied (publickey,gssapi-keyex,gssapi-with-mic).", "unreachable": true}
2019-11-01 06:50:49,755 p=5916 u=bala |  PLAY RECAP *********************************************************************
2019-11-01 06:50:49,755 p=5916 u=bala |  34.69.108.215              : ok=0    changed=0    unreachable=1    failed=0    skipped=0    rescued=0    ignored=0   
2019-11-01 06:50:49,755 p=5916 u=bala |  35.226.36.29               : ok=0    changed=0    unreachable=1    failed=0    skipped=0    rescued=0    ignored=0   
2019-11-01 06:58:29,507 p=6085 u=bala |  PLAY [test] ********************************************************************
2019-11-01 06:58:29,517 p=6085 u=bala |  TASK [Gathering Facts] *********************************************************
2019-11-01 06:58:29,671 p=6085 u=bala |  fatal: [35.226.36.29]: UNREACHABLE! => {"changed": false, "msg": "Failed to connect to the host via ssh: Permission denied (publickey,gssapi-keyex,gssapi-with-mic).", "unreachable": true}
2019-11-01 06:58:29,675 p=6085 u=bala |  fatal: [34.69.108.215]: UNREACHABLE! => {"changed": false, "msg": "Failed to connect to the host via ssh: Permission denied (publickey,gssapi-keyex,gssapi-with-mic).", "unreachable": true}
2019-11-01 06:58:29,677 p=6085 u=bala |  PLAY RECAP *********************************************************************
2019-11-01 06:58:29,677 p=6085 u=bala |  34.69.108.215              : ok=0    changed=0    unreachable=1    failed=0    skipped=0    rescued=0    ignored=0   
2019-11-01 06:58:29,677 p=6085 u=bala |  35.226.36.29               : ok=0    changed=0    unreachable=1    failed=0    skipped=0    rescued=0    ignored=0   
2019-11-01 07:22:27,153 p=6537 u=bala |  ERROR! Unexpected Exception, this is probably a bug: [Errno 32] Broken pipe
2019-11-01 07:22:27,154 p=6537 u=bala |  to see the full traceback, use -vvv
2019-11-01 07:22:27,154 p=6537 u=bala |  the full traceback was:

Traceback (most recent call last):
  File "/usr/bin/ansible-doc", line 110, in <module>
    exit_code = cli.run()
  File "/usr/lib/python2.7/site-packages/ansible/cli/doc.py", line 118, in run
    DocCLI.pager(self.get_plugin_list_text(loader))
  File "/usr/lib/python2.7/site-packages/ansible/cli/__init__.py", line 425, in pager
    display.display(text, screen_only=True)
  File "/usr/lib/python2.7/site-packages/ansible/utils/display.py", line 153, in display
    fileobj.write(msg2)
IOError: [Errno 32] Broken pipe

2019-11-01 07:30:57,611 p=6656 u=bala |  34.69.108.215 | UNREACHABLE! => {
    "changed": false, 
    "msg": "Failed to connect to the host via ssh: Permission denied (publickey,gssapi-keyex,gssapi-with-mic).", 
    "unreachable": true
}
2019-11-01 07:30:57,619 p=6656 u=bala |  35.226.36.29 | UNREACHABLE! => {
    "changed": false, 
    "msg": "Failed to connect to the host via ssh: Permission denied (publickey,gssapi-keyex,gssapi-with-mic).", 
    "unreachable": true
}
2019-11-01 07:31:21,742 p=6673 u=bala |  34.69.108.215 | UNREACHABLE! => {
    "changed": false, 
    "msg": "Failed to connect to the host via ssh: Permission denied (publickey,gssapi-keyex,gssapi-with-mic).", 
    "unreachable": true
}
2019-11-01 07:31:21,746 p=6673 u=bala |  35.226.36.29 | UNREACHABLE! => {
    "changed": false, 
    "msg": "Failed to connect to the host via ssh: Permission denied (publickey,gssapi-keyex,gssapi-with-mic).", 
    "unreachable": true
}
